<?xml version="1.0" encoding="UTF-8"?>
<testng-results skipped="0" failed="1" total="1" passed="0">
  <reporter-output>
  </reporter-output>
  <suite name="Default suite" duration-ms="1054" started-at="2014-04-03T02:00:15Z" finished-at="2014-04-03T02:00:16Z">
    <groups>
    </groups>
    <test name="Default test" duration-ms="1054" started-at="2014-04-03T02:00:15Z" finished-at="2014-04-03T02:00:16Z">
      <class name="org.kits.trax.rest.CoverageControllerIT">
        <test-method status="FAIL" signature="list(java.util.List)[pri:0, instance:org.kits.trax.rest.CoverageControllerIT@59d57c39]" name="list" duration-ms="276" started-at="2014-04-02T22:00:16Z" data-provider="listData" finished-at="2014-04-02T22:00:16Z">
          <params>
            <param index="0">
              <value>
                <![CDATA[[org.kits.trax.domain.Coverage@65a09e0b, org.kits.trax.domain.Coverage@13e8184d, org.kits.trax.domain.Coverage@6a937170, org.kits.trax.domain.Coverage@75fca6b9, org.kits.trax.domain.Coverage@1e25f833, org.kits.trax.domain.Coverage@4ec9ebbb, org.kits.trax.domain.Coverage@2a936a66, org.kits.trax.domain.Coverage@342e6460, org.kits.trax.domain.Coverage@51bff563, org.kits.trax.domain.Coverage@11876083]]]>
              </value>
            </param>
          </params>
          <exception class="java.lang.AssertionError">
            <message>
              <![CDATA[expected [200] but found [405]]]>
            </message>
            <full-stacktrace>
              <![CDATA[java.lang.AssertionError: expected [200] but found [405]
	at org.testng.Assert.fail(Assert.java:94)
	at org.testng.Assert.failNotEquals(Assert.java:494)
	at org.testng.Assert.assertEquals(Assert.java:123)
	at org.testng.Assert.assertEquals(Assert.java:370)
	at org.testng.Assert.assertEquals(Assert.java:380)
	at org.kits.trax.rest.CoverageControllerIT.list(CoverageControllerIT.java:95)
	at sun.reflect.NativeMethodAccessorImpl.invoke0(Native Method)
	at sun.reflect.NativeMethodAccessorImpl.invoke(Unknown Source)
	at sun.reflect.DelegatingMethodAccessorImpl.invoke(Unknown Source)
	at java.lang.reflect.Method.invoke(Unknown Source)
	at org.testng.internal.MethodInvocationHelper.invokeMethod(MethodInvocationHelper.java:84)
	at org.testng.internal.Invoker.invokeMethod(Invoker.java:714)
	at org.testng.internal.Invoker.invokeTestMethod(Invoker.java:901)
	at org.testng.internal.Invoker.invokeTestMethods(Invoker.java:1231)
	at org.testng.internal.TestMethodWorker.invokeTestMethods(TestMethodWorker.java:127)
	at org.testng.internal.TestMethodWorker.run(TestMethodWorker.java:111)
	at org.testng.TestRunner.privateRun(TestRunner.java:767)
	at org.testng.TestRunner.run(TestRunner.java:617)
	at org.testng.SuiteRunner.runTest(SuiteRunner.java:334)
	at org.testng.SuiteRunner.runSequentially(SuiteRunner.java:329)
	at org.testng.SuiteRunner.privateRun(SuiteRunner.java:291)
	at org.testng.SuiteRunner.run(SuiteRunner.java:240)
	at org.testng.SuiteRunnerWorker.runSuite(SuiteRunnerWorker.java:52)
	at org.testng.SuiteRunnerWorker.run(SuiteRunnerWorker.java:86)
	at org.testng.TestNG.runSuitesSequentially(TestNG.java:1224)
	at org.testng.TestNG.runSuitesLocally(TestNG.java:1149)
	at org.testng.TestNG.run(TestNG.java:1057)
	at org.testng.remote.RemoteTestNG.run(RemoteTestNG.java:111)
	at org.testng.remote.RemoteTestNG.initAndRun(RemoteTestNG.java:204)
	at org.testng.remote.RemoteTestNG.main(RemoteTestNG.java:175)
]]>
            </full-stacktrace>
          </exception> <!-- java.lang.AssertionError -->
          <reporter-output>
          </reporter-output>
        </test-method> <!-- list -->
      </class> <!-- org.kits.trax.rest.CoverageControllerIT -->
    </test> <!-- Default test -->
  </suite> <!-- Default suite -->
</testng-results>
